Workbook
Name d_Category: 'Cleaned Data'!$D$2:$D$2001
Name d_City: 'Cleaned Data'!$U$2:$U$2001
Name d_COGS: 'Cleaned Data'!$M$2:$M$2001
Name d_Cust: 'Cleaned Data'!$S$2:$S$2001
Name d_Date: 'Cleaned Data'!$B$2:$B$2001
Name d_Disc: 'Cleaned Data'!$G$2:$G$2001
Name d_GP: 'Cleaned Data'!$N$2:$N$2001
Name d_Inv: 'Cleaned Data'!$A$2:$A$2001
Name d_NetQty: 'Cleaned Data'!$K$2:$K$2001
Name d_NetSales: 'Cleaned Data'!$L$2:$L$2001
Name d_NP: 'Cleaned Data'!$Q$2:$Q$2001
Name d_Opex: 'Cleaned Data'!$P$2:$P$2001
Name d_Pay: 'Cleaned Data'!$T$2:$T$2001
Name d_Product: 'Cleaned Data'!$C$2:$C$2001
Name d_Qty: 'Cleaned Data'!$E$2:$E$2001
Name d_RetQty: 'Cleaned Data'!$I$2:$I$2001
Name d_Sales: 'Cleaned Data'!$H$2:$H$2001
Name d_SalesRet: 'Cleaned Data'!$J$2:$J$2001
Name fCat: Calc!$C$5
Name fCity: Calc!$C$6
Name fCust: Calc!$C$7
Name fEnd: Calc!$C$13
Name fPay: Calc!$C$8
Name fStart: Calc!$C$12

Sheet Requirements
A1: Requirement | B1: Details
A2: Client / Retail Store | B2: Mega Market
A3: Raw Dataset | B3: 2,000+ retail transaction rows; raw data may contain duplicates, blanks, inconsistent text formatting, mixed data types, and other realistic data-quality issues.
A4: Deliverable 1 — Data Cleaning | B4: Clean duplicates; standardize product/category/payment/customer/city text; handle missing values; convert dates and numeric fields to consistent formats; validate quantities and financial calculations.
A5: Deliverable 2 — Data Organization | B5: Create a structured, analysis-ready dataset with consistent column names, logical ordering, and calculated fields such as Net Qty, Net Sales, Gross Profit, and Net Profit.
A6: Deliverable 3 — Formatting | B6: Apply professional Excel formatting: headers, currency/percentage/number/date formats, filters, freeze panes, readable column widths, and conditional formatting where useful.
A7: Deliverable 4 — HTML Dashboard | B7: Create a professional interactive HTML dashboard for Mega Market using the cleaned data. Include KPI cards, sales/profit trends, product/category analysis, and useful filters/charts.
A8: Dashboard KPI Requirements | B8: Total Sales, Net Sales, Gross Profit, Net Profit, Total Quantity Sold, Average Order Value, Return Rate, and Gross/Net Profit Margin.
A9: Product Analysis | B9: Identify highest-selling product, lowest-selling product, highest-revenue product, lowest-revenue product, and products with weak sales performance.
A10: Category Analysis | B10: Compare categories by Net Sales, Quantity, Gross Profit, Net Profit, and margins. Highlight strong and weak categories.
A11: Trend Analysis | B11: Show monthly Net Sales, Gross Profit, Net Profit, and transaction/order trends. Identify peak and weak periods.
A12: Customer & Payment Analysis | B12: Analyze customer type, payment method, and city contribution to sales.
... A18: Important | B18: Do not change valid business values merely to make the dataset look perfect. Document assumptions used while cleaning missing or inconsistent values.

Sheet Raw Data
A1: Invoice ID | B1: Date | C1: Product | D1: Category | E1: Qty | F1: Unit Price (₹) | G1: Discount (%) | H1: Sales (₹) | I1: Return Qty | J1: Sales Return (₹) | K1: Net Qty | L1: Net Sales (₹) | M1: COGS (₹) | N1: Gross Profit (₹) | O1: Operating Expense (₹) | P1: Net Profit (₹) | Q1: Customer Type | R1: Payment Method | S1: City
A2: MM-0001 | B2: 45872 | C2: Biscuits Pack | D2: Snacks | E2: 5 | F2: 40 | G2: 0 | H2: 200 | I2: 0 | J2: 0 | K2: 5 | L2: 200 | M2: 161.43 | N2: 38.57 | O2: 17.13 | P2: 21.44 | Q2: Member | R2: Card | S2: Ghaziabad
A3: MM-0002 | B3: 45849 | C3: Cooking Oil 1L | D3: Groceries | E3: 1 | F3: 145 | G3: 2 | H3: 142.1 | I3: 0 | J3: 0 | K3: 1 | L3: 142.1 | M3: 90.03 | N3: 52.07 | O3: 17.77 | P3: 34.3 | Q3: Walk-in | R3: Cash | S3: Delhi
A4: MM-0003 | B4: 45845 | C4: Shampoo 340ml | D4: Personal Care | E4: 3 | F4: 210 | G4: 0 | H4: 630 | I4: 0 | J4: 0 | K4: 3 | L4: 630 | M4: 394.09 | N4: 235.91 | O4: 51.65 | P4: 184.26 | Q4: Walk-in | R4: Card | S4: Noida
A5: MM-0004 | B5: 45792 | C5: Laundry Detergent 2kg | D5: Household | E5: 3 | F5: 280 | G5: 0 | H5: 840 | I5: 0 | J5: 0 | K5: 3 | L5: 840 | M5: 719.02 | N5: 120.98 | O5: 99.79 | P5: 21.19 | Q5: Regular | R5: Cash | S5: Gurugram
A6: MM-0005 | B6: 45820 | C6: LED Bulb 9W | D6: Electronics | E6: 8 | F6: 120 | G6: 15 | H6: 816 | I6: 0 | J6: 0 | K6: 8 | L6: 816 | M6: 664.24 | N6: 151.76 | O6: 47.18 | P6: 104.58 | Q6: Walk-in | R6: Card | S6: Ghaziabad
A7: MM-0006 | B7: 45659 | C7: Biscuits Pack | D7: Snacks | E7: 3 | F7: 40 | G7: 5 | H7: 114 | I7: 0 | J7: 0 | K7: 3 | L7: 114 | M7: 75.42 | N7: 38.58 | O7: 7.36 | P7: 31.22 | Q7: New | R7: UPI | S7: Noida
A8: MM-0007 | B8: 45927 | C8: Soft Drink 750ml | D8: Beverages | E8: 3 | F8: 48 | G8: 0 | H8: 144 | I8: 0 | J8: 0 | K8: 3 | L8: 144 | M8: 118.39 | N8: 25.61 | O8: 11.75 | P8: 13.86 | Q8: Member | R8: Wallet | S8: Gurugram
A9: MM-0008 | B9: 45710 | C9: Potato Chips | D9: Snacks | E9: 3 | F9: 30 | G9: 0 | H9: 90 | I9: 0 | J9: 0 | K9: 3 | L9: 90 | M9: 76.56 | N9: 13.44 | O9: 9.88 | P9: 3.56 | Q9: Walk-in | R9: UPI | S9: Delhi
A10: MM-0009 | B10: 45793 | C10: Soap Bar | D10: Personal Care | E10: 1 | F10: 38 | G10: 5 | H10: 36.1 | I10: 0 | J10: 0 | K10: 1 | L10: 36.1 | M10: 23.03 | N10: 13.07 | O10: 4.04 | P10: 9.03 | Q10: Walk-in | R10: Card | S10: Gurugram
A11: MM-0010 | B11: 45698 | C11: Batteries Pack | D11: Electronics | E11: 4 | F11: 85 | G11: 5 | H11: 323 | I11: 0 | J11: 0 | K11: 4 | L11: 323 | M11: 260.05 | N11: 62.95 | O11: 25.41 | P11: 37.54 | Q11: Walk-in | R11: Card | S11: Delhi
A12: MM-0011 | B12: 45829 | C12: Potato Chips | D12: Snacks | E12: 3 | F12: 30 | G12: 0 | H12: 90 | I12: 0 | J12: 0 | K12: 3 | L12: 90 | M12: 63.81 | N12: 26.19 | O12: 9.29 | P12: 16.9 | Q12: Walk-in | R12: UPI | S12: Gurugram
A13: MM-0012 | B13: 45912 | C13: Sugar 1kg | D13: Groceries | E13: 3 | F13: 52 | G13: 0 | H13: 156 | I13: 0 | J13: 0 | K13: 3 | L13: 156 | M13: 123.42 | N13: 32.58 | O13: 14.8 | P13: 17.78 | Q13: New | R13: Card | S13: Gurugram
A14: MM-0013 | B14: 45898 | C14: Chocolate Bar | D14: Snacks | E14: 4 | F14: 55 | G14: 0 | H14: 220 | I14: 0 | J14: 0 | K14: 4 | L14: 220 | M14: 159.6 | N14: 60.4 | O14: 26.77 | P14: 33.63 | Q14: Walk-in | R14: Cash | S14: Ghaziabad
... A23: MM-0022 | B23: 45785 | C23: Cooking Oil 1L | D23: Groceries | E23: 1 | F23: 145 | G23: 0 | H23: 145 | I23: 0 | J23: 0 | K23: 1 | L23: 145 | M23: 97.78 | N23: 47.22 | O23: 9.27 | P23: 37.95 | Q23: Member | R23: UPI | S23: Ghaziabad
A24: MM-0023 | B24: 45920 | C24: Rice 5kg | D24: Groceries | E24: 4 | F24: 420 | G24: 5 | H24: 1596 | I24: 0 | J24: 0 | K24: 4 | L24: 1596 | M24: 1069.6 | N24: 526.4 | O24: 168.64 | P24: 357.76 | Q24: Walk-in | R24: Wallet | S24: Noida
A25: MM-0024 | B25: 45694 | C25: Dishwash Liquid 500ml | D25: Household | E25: 3 | F25: 95 | G25: 0 | H25: 285 | I25: 0 | J25: 0 | K25: 3 | L25: 285 | M25: 193.24 | N25: 91.76 | O25: 34.71 | P25: 57.05 | Q25: Walk-in | R25: Card | S25: Gurugram
A26: MM-0025 | B26: 45818 | C26: Chocolate Bar | D26: Snacks | E26: 2 | F26: 55 | G26: 5 | H26: 104.5 | I26: 0 | J26: 0 | K26: 2 | L26: 104.5 | M26: 86.02 | N26: 18.48 | O26: 8.61 | P26: 9.87 | Q26: Walk-in | R26: Wallet | S26: Gurugram
A27: MM-0026 | B27: 45810 | C27: Floor Cleaner 1L | D27: Household | E27: 1 | F27: 125 | G27: 10 | H27: 112.5 | I27: 1 | J27: 112.5 | K27: 0 | L27: 0 | M27: 0 | N27: 0 | O27: 0 | P27: 0 | Q27: Regular | R27: UPI | S27: Ghaziabad
A28: MM-0027 | B28: 45946 | C28: Toothpaste 150g | D28: Personal Care | E28: 3 | F28: 110 | G28: 2 | H28: 323.4 | I28: 0 | J28: 0 | K28: 3 | L28: 323.4 | M28: 251.11 | N28: 72.29 | O28: 34.6 | P28: 37.69 | Q28: New | R28: Cash | S28: Ghaziabad
A29: MM-0028 | B29: 45679 | C29: Notebook | D29: Stationery | E29: 2 | F29: 65 | G29: 5 | H29: 123.5 | I29: 0 | J29: 0 | K29: 2 | L29: 123.5 | M29: 97.94 | N29: 25.56 | O29: 11.54 | P29: 14.02 | Q29: New | R29: UPI | S29: Noida
A30: MM-0029 | B30: 45941 | C30: Coffee 200g | D30: Beverages | E30: 2 | F30: 180 | G30: 10 | H30: 324 | I30: 0 | J30: 0 | K30: 2 | L30: 324 | M30: 249.96 | N30: 74.04 | O30: 29.23 | P30: 44.81 | Q30: Member | R30: Wallet | S30: Delhi
A31: MM-0030 | B31: 45829 | C31: Tea 250g | D31: Beverages | E31: 2 | F31: 125 | G31: 0 | H31: 250 | I31: 0 | J31: 0 | K31: 2 | L31: 250 | M31: 189.32 | N31: 60.68 | O31: 13.37 | P31: 47.31 | Q31: Walk-in | R31: UPI | S31: Delhi
A32: MM-0031 | B32: 45838 | C32: Toothpaste 150g | D32: Personal Care | E32: 6 | F32: 110 | G32: 0 | H32: 660 | I32: 0 | J32: 0 | K32: 6 | L32: 660 | M32: 411.65 | N32: 248.35 | O32: 55.61 | P32: 192.74 | Q32: Member | R32: Card | S32: Ghaziabad
A33: MM-0032 | B33: 45675 | C33: Rice 5kg | D33: groceries | E33: 1 | F33: 420 | G33: 0 | H33: 420 | I33: 0 | J33: 0 | K33: 1 | L33: 420 | M33: 279.64 | N33: 140.36 | O33: 37.31 | P33: 103.05 | Q33: Regular | R33: UPI | S33: Gurugram
A34: MM-0033 | B34: 45812 | C34: Sugar 1kg | D34: Groceries | E34: 3 | F34: 52 | G34: 0 | H34: 156 | I34: 0 | J34: 0 | K34: 3 | L34: 156 | M34: 119.75 | N34: 36.25 | O34: 9.55 | P34: 26.7 | Q34: New | R34: UPI | S34: Noida
A35: MM-0034 | B35: 45683 | C35: Floor Cleaner 1L | D35: Household | E35: 5 | F35: 125 | G35: 0 | H35: 625 | I35: 0 | J35: 0 | K35: 5 | L35: 625 | M35: 493.84 | N35: 131.16 | O35: 46.08 | P35: 85.08 | Q35: Member | R35: UPI
A36: MM-0035 | B36: 45799 | C36: Soap Bar | D36: Personal Care | E36: 1 | F36: 38 | G36: 0 | H36: 38 | I36: 0 | J36: 0 | K36: 1 | L36: 38 | M36: 29.29 | N36: 8.71 | O36: 2.12 | P36: 6.59 | Q36: Walk-in | R36: Card | S36: Gurugram
A37: MM-0036 | B37: 45720 | C37: Laundry Detergent 2kg | D37: Household | E37: 2 | F37: 280 | G37: 0 | H37: 560 | I37: 0 | J37: 0 | K37: 2 | L37: 560 | M37: 424.92 | N37: 135.08 | O37: 48.86 | P37: 86.22 | Q37: New | R37: Cash | S37: Noida
A38: MM-0037 | B38: 45710 | C38: Floor Cleaner 1L | D38: Household | E38: 1 | F38: 125 | G38: 5 | H38: 118.75 | I38: 0 | J38: 0 | K38: 1 | L38: 118.75 | M38: 83.89 | N38: 34.86 | O38: 10.9 | P38: 23.96 | Q38: Walk-in | R38: Wallet | S38: Ghaziabad
A39: MM-0038 | B39: 45965 | C39: Tea 250g | D39: Beverages | E39: 3 | F39: 125 | G39: 5 | H39: 356.25 | I39: 0 | J39: 0 | K39: 3 | L39: 356.25 | M39: 237.49 | N39: 118.76 | O39: 37.75 | P39: 81.01 | Q39: Walk-in | R39: Cash | S39: Noida
A40: MM-0039 | B40: 45886 | C40: Soft Drink 750ml | D40: Beverages | E40: 2 | F40: 48 | G40: 5 | H40: 91.2 | I40: 0 | J40: 0 | K40: 2 | L40: 91.2 | M40: 62.47 | N40: 28.73 | O40: 5.13 | P40: 23.6 | Q40: New | R40: Cash | S40: Noida
A41: MM-0040 | B41: 45775 | C41: Chocolate Bar | D41: Snacks | E41: 4 | F41: 55 | G41: 0 | H41: 220 | I41: 0 | J41: 0 | K41: 4 | L41: 220 | M41: 184.72 | N41: 35.28 | O41: 15.22 | P41: 20.06 | R41: Cash | S41: Ghaziabad
A42: MM-0041 | B42: 45904 | C42: Soap Bar | D42: Personal Care | E42: 2 | F42: 38 | G42: 15 | H42: 64.6 | I42: 0 | J42: 0 | K42: 2 | L42: 64.6 | M42: 51.49 | N42: 13.11 | O42: 6.39 | P42: 6.72 | Q42: Member | R42: Wallet | S42: Noida
A43: MM-0042 | B43: 45751 | C43: Dishwash Liquid 500ml | D43: Household | E43: 1 | F43: 95 | G43: 0 | H43: 95 | I43: 0 | J43: 0 | K43: 1 | L43: 95 | M43: 66.69 | N43: 28.31 | O43: 5.47 | P43: 22.84 | Q43: New | R43: UPI | S43: Ghaziabad
A44: MM-0043 | B44: 45879 | C44: Tea 250g | D44: Beverages | E44: 3 | F44: 125 | G44: 0 | H44: 375 | I44: 0 | J44: 0 | K44: 3 | L44: 375 | M44: 276.75 | N44: 98.25 | O44: 23.95 | P44: 74.3 | Q44: Regular | R44: Card | S44: Noida
A45: MM-0044 | B45: 45914 | C45: Soft Drink 750ml | D45: Beverages | E45: 8 | F45: 48 | G45: 10 | H45: 345.6 | I45: 1 | J45: 43.2 | K45: 7 | L45: 302.4 | M45: 206.42 | N45: 95.98 | O45: 27.29 | P45: 68.69 | Q45: Walk-in | R45: Cash | S45: Delhi
A46: MM-0045 | B46: 45997 | C46: Cooking Oil 1L | D46: Groceries | E46: 3 | F46: 145 | G46: 10 | H46: 391.5 | I46: 0 | J46: 0 | K46: 3 | L46: 391.5 | M46: 331.45 | N46: 60.05 | O46: 39.51 | P46: 20.54 | Q46: Walk-in | R46: Wallet | S46: Noida
A47: MM-0046 | B47: 45825 | C47: Sugar 1kg | D47: Groceries | E47: 4 | F47: 52 | G47: 0 | H47: 208 | I47: 0 | J47: 0 | K47: 4 | L47: 208 | M47: 156.2 | N47: 51.8 | O47: 16.82 | P47: 34.98 | Q47: New | R47: Card | S47: Ghaziabad
A48: MM-0047 | B48: 45747 | C48: Soap Bar | D48: Personal Care | E48: 1 | F48: 38 | G48: 0 | H48: 38 | I48: 0 | J48: 0 | K48: 1 | L48: 38 | M48: 23.92 | N48: 14.08 | O48: 2.92 | P48: 11.16 | Q48: Walk-in | R48: Cash | S48: Noida
...

Sheet Cleaned Data
A1: Invoice ID | B1: Date | C1: Product | D1: Category | E1: Qty | F1: Unit Price (₹) | G1: Discount (%) | H1: Sales (₹) | I1: Return Qty | J1: Sales Return (₹) | K1: Net Qty | L1: Net Sales (₹) | M1: COGS (₹) | N1: Gross Profit (₹) | O1: Gross Profit Margin | P1: Operating Expense (₹) | Q1: Net Profit (₹) | R1: Net Profit Margin | S1: Customer Type | T1: Payment Method | U1: City
A2: MM-0001 | B2: 45872 | C2: Biscuits Pack | D2: Snacks | E2: 5 | F2: 40 | G2: 0 | H2: 200 | I2: 0 | J2: 0 | K2: 5 | L2: 200 | M2: 161.43 | N2: 38.57 | O2: =N2/L2 -> 0.19285 | P2: 17.13 | Q2: 21.44 | R2: =Q2/L2 -> 0.1072 | S2: Member | T2: Card | U2: Ghaziabad
A3: MM-0002 | B3: 45849 | C3: Cooking Oil 1L | D3: Groceries | E3: 1 | F3: 145 | G3: 0.02 | H3: 142.1 | I3: 0 | J3: 0 | K3: 1 | L3: 142.1 | M3: 90.03 | N3: 52.07 | O3: =N3/L3 -> 0.36643209 | P3: 17.77 | Q3: 34.3 | R3: =Q3/L3 -> 0.24137931 | S3: Walk-in | T3: Cash | U3: Delhi
A4: MM-0003 | B4: 45845 | C4: Shampoo 340ml | D4: Personal Care | E4: 3 | F4: 210 | G4: 0 | H4: 630 | I4: 0 | J4: 0 | K4: 3 | L4: 630 | M4: 394.09 | N4: 235.91 | O4: =N4/L4 -> 0.37446032 | P4: 51.65 | Q4: 184.26 | R4: =Q4/L4 -> 0.29247619 | S4: Walk-in | T4: Card | U4: Noida
A5: MM-0004 | B5: 45792 | C5: Laundry Detergent 2kg | D5: Household | E5: 3 | F5: 280 | G5: 0 | H5: 840 | I5: 0 | J5: 0 | K5: 3 | L5: 840 | M5: 719.02 | N5: 120.98 | O5: =N5/L5 -> 0.14402381 | P5: 99.79 | Q5: 21.19 | R5: =Q5/L5 -> 0.02522619 | S5: Regular | T5: Cash | U5: Gurugram
A6: MM-0005 | B6: 45820 | C6: LED Bulb 9W | D6: Electronics | E6: 8 | F6: 120 | G6: 0.15 | H6: 816 | I6: 0 | J6: 0 | K6: 8 | L6: 816 | M6: 664.24 | N6: 151.76 | O6: =N6/L6 -> 0.18598039 | P6: 47.18 | Q6: 104.58 | R6: =Q6/L6 -> 0.12816176 | S6: Walk-in | T6: Card | U6: Ghaziabad
A7: MM-0006 | B7: 45659 | C7: Biscuits Pack | D7: Snacks | E7: 3 | F7: 40 | G7: 0.05 | H7: 114 | I7: 0 | J7: 0 | K7: 3 | L7: 114 | M7: 75.42 | N7: 38.58 | O7: =N7/L7 -> 0.33842105 | P7: 7.36 | Q7: 31.22 | R7: =Q7/L7 -> 0.27385965 | S7: New | T7: UPI | U7: Noida
A8: MM-0007 | B8: 45927 | C8: Soft Drink 750ml | D8: Beverages | E8: 3 | F8: 48 | G8: 0 | H8: 144 | I8: 0 | J8: 0 | K8: 3 | L8: 144 | M8: 118.39 | N8: 25.61 | O8: =N8/L8 -> 0.17784722 | P8: 11.75 | Q8: 13.86 | R8: =Q8/L8 -> 0.09625 | S8: Member | T8: Wallet | U8: Gurugram
A9: MM-0008 | B9: 45710 | C9: Potato Chips | D9: Snacks | E9: 3 | F9: 30 | G9: 0 | H9: 90 | I9: 0 | J9: 0 | K9: 3 | L9: 90 | M9: 76.56 | N9: 13.44 | O9: =N9/L9 -> 0.14933333 | P9: 9.88 | Q9: 3.56 | R9: =Q9/L9 -> 0.039555556 | S9: Walk-in | T9: UPI | U9: Delhi
A10: MM-0009 | B10: 45793 | C10: Soap Bar | D10: Personal Care | E10: 1 | F10: 38 | G10: 0.05 | H10: 36.1 | I10: 0 | J10: 0 | K10: 1 | L10: 36.1 | M10: 23.03 | N10: 13.07 | O10: =N10/L10 -> 0.36204986 | P10: 4.04 | Q10: 9.03 | R10: =Q10/L10 -> 0.2501385 | S10: Walk-in | T10: Card | U10: Gurugram
A11: MM-0010 | B11: 45698 | C11: Batteries Pack | D11: Electronics | E11: 4 | F11: 85 | G11: 0.05 | H11: 323 | I11: 0 | J11: 0 | K11: 4 | L11: 323 | M11: 260.05 | N11: 62.95 | O11: =N11/L11 -> 0.19489164 | P11: 25.41 | Q11: 37.54 | R11: =Q11/L11 -> 0.11622291 | S11: Walk-in | T11: Card | U11: Delhi
A12: MM-0011 | B12: 45829 | C12: Potato Chips | D12: Snacks | E12: 3 | F12: 30 | G12: 0 | H12: 90 | I12: 0 | J12: 0 | K12: 3 | L12: 90 | M12: 63.81 | N12: 26.19 | O12: =N12/L12 -> 0.291 | P12: 9.29 | Q12: 16.9 | R12: =Q12/L12 -> 0.18777778 | S12: Walk-in | T12: UPI | U12: Gurugram
A13: MM-0012 | B13: 45912 | C13: Sugar 1kg | D13: Groceries | E13: 3 | F13: 52 | G13: 0 | H13: 156 | I13: 0 | J13: 0 | K13: 3 | L13: 156 | M13: 123.42 | N13: 32.58 | O13: =N13/L13 -> 0.20884615 | P13: 14.8 | Q13: 17.78 | R13: =Q13/L13 -> 0.11397436 | S13: New | T13: Card | U13: Gurugram
... A26: MM-0025 | B26: 45818 | C26: Chocolate Bar | D26: Snacks | E26: 2 | F26: 55 | G26: 0.05 | H26: 104.5 | I26: 0 | J26: 0 | K26: 2 | L26: 104.5 | M26: 86.02 | N26: 18.48 | O26: =N26/L26 -> 0.17684211 | P26: 8.61 | Q26: 9.87 | R26: =Q26/L26 -> 0.094449761 | S26: Walk-in | T26: Wallet | U26: Gurugram
A27: MM-0026 | B27: 45810 | C27: Floor Cleaner 1L | D27: Household | E27: 1 | F27: 125 | G27: 0.1 | H27: 112.5 | I27: 1 | J27: 112.5 | K27: 0 | L27: 0 | M27: 0 | N27: 0 | O27: 0 | P27: 0 | Q27: 0 | R27: 0 | S27: Regular | T27: UPI | U27: Ghaziabad
A28: MM-0027 | B28: 45946 | C28: Toothpaste 150g | D28: Personal Care | E28: 3 | F28: 110 | G28: 0.02 | H28: 323.4 | I28: 0 | J28: 0 | K28: 3 | L28: 323.4 | M28: 251.11 | N28: 72.29 | O28: =N28/L28 -> 0.22353123 | P28: 34.6 | Q28: 37.69 | R28: =Q28/L28 -> 0.11654298 | S28: New | T28: Cash | U28: Ghaziabad
A29: MM-0028 | B29: 45679 | C29: Notebook | D29: Stationery | E29: 2 | F29: 65 | G29: 0.05 | H29: 123.5 | I29: 0 | J29: 0 | K29: 2 | L29: 123.5 | M29: 97.94 | N29: 25.56 | O29: =N29/L29 -> 0.20696356 | P29: 11.54 | Q29: 14.02 | R29: =Q29/L29 -> 0.11352227 | S29: New | T29: UPI | U29: Noida
A30: MM-0029 | B30: 45941 | C30: Coffee 200g | D30: Beverages | E30: 2 | F30: 180 | G30: 0.1 | H30: 324 | I30: 0 | J30: 0 | K30: 2 | L30: 324 | M30: 249.96 | N30: 74.04 | O30: =N30/L30 -> 0.22851852 | P30: 29.23 | Q30: 44.81 | R30: =Q30/L30 -> 0.13830247 | S30: Member | T30: Wallet | U30: Delhi
A31: MM-0030 | B31: 45829 | C31: Tea 250g | D31: Beverages | E31: 2 | F31: 125 | G31: 0 | H31: 250 | I31: 0 | J31: 0 | K31: 2 | L31: 250 | M31: 189.32 | N31: 60.68 | O31: =N31/L31 -> 0.24272 | P31: 13.37 | Q31: 47.31 | R31: =Q31/L31 -> 0.18924 | S31: Walk-in | T31: UPI | U31: Delhi
A32: MM-0031 | B32: 45838 | C32: Toothpaste 150g | D32: Personal Care | E32: 6 | F32: 110 | G32: 0 | H32: 660 | I32: 0 | J32: 0 | K32: 6 | L32: 660 | M32: 411.65 | N32: 248.35 | O32: =N32/L32 -> 0.37628788 | P32: 55.61 | Q32: 192.74 | R32: =Q32/L32 -> 0.2920303 | S32: Member | T32: Card | U32: Ghaziabad
A33: MM-0032 | B33: 45675 | C33: Rice 5kg | D33: Groceries | E33: 1 | F33: 420 | G33: 0 | H33: 420 | I33: 0 | J33: 0 | K33: 1 | L33: 420 | M33: 279.64 | N33: 140.36 | O33: =N33/L33 -> 0.33419048 | P33: 37.31 | Q33: 103.05 | R33: =Q33/L33 -> 0.24535714 | S33: Regular | T33: UPI | U33: Gurugram
A34: MM-0033 | B34: 45812 | C34: Sugar 1kg | D34: Groceries | E34: 3 | F34: 52 | G34: 0 | H34: 156 | I34: 0 | J34: 0 | K34: 3 | L34: 156 | M34: 119.75 | N34: 36.25 | O34: =N34/L34 -> 0.23237179 | P34: 9.55 | Q34: 26.7 | R34: =Q34/L34 -> 0.17115385 | S34: New | T34: UPI | U34: Noida
A35: MM-0034 | B35: 45683 | C35: Floor Cleaner 1L | D35: Household | E35: 5 | F35: 125 | G35: 0 | H35: 625 | I35: 0 | J35: 0 | K35: 5 | L35: 625 | M35: 493.84 | N35: 131.16 | O35: =N35/L35 -> 0.209856 | P35: 46.08 | Q35: 85.08 | R35: =Q35/L35 -> 0.136128 | S35: Member | T35: UPI | U35: Unknown
A36: MM-0035 | B36: 45799 | C36: Soap Bar | D36: Personal Care | E36: 1 | F36: 38 | G36: 0 | H36: 38 | I36: 0 | J36: 0 | K36: 1 | L36: 38 | M36: 29.29 | N36: 8.71 | O36: =N36/L36 -> 0.22921053 | P36: 2.12 | Q36: 6.59 | R36: =Q36/L36 -> 0.17342105 | S36: Walk-in | T36: Card | U36: Gurugram
A37: MM-0036 | B37: 45720 | C37: Laundry Detergent 2kg | D37: Household | E37: 2 | F37: 280 | G37: 0 | H37: 560 | I37: 0 | J37: 0 | K37: 2 | L37: 560 | M37: 424.92 | N37: 135.08 | O37: =N37/L37 -> 0.24121429 | P37: 48.86 | Q37: 86.22 | R37: =Q37/L37 -> 0.15396429 | S37: New | T37: Cash | U37: Noida
A38: MM-0037 | B38: 45710 | C38: Floor Cleaner 1L | D38: Household | E38: 1 | F38: 125 | G38: 0.05 | H38: 118.75 | I38: 0 | J38: 0 | K38: 1 | L38: 118.75 | M38: 83.89 | N38: 34.86 | O38: =N38/L38 -> 0.29355789 | P38: 10.9 | Q38: 23.96 | R38: =Q38/L38 -> 0.20176842 | S38: Walk-in | T38: Wallet | U38: Ghaziabad
A39: MM-0038 | B39: 45965 | C39: Tea 250g | D39: Beverages | E39: 3 | F39: 125 | G39: 0.05 | H39: 356.25 | I39: 0 | J39: 0 | K39: 3 | L39: 356.25 | M39: 237.49 | N39: 118.76 | O39: =N39/L39 -> 0.3333614 | P39: 37.75 | Q39: 81.01 | R39: =Q39/L39 -> 0.22739649 | S39: Walk-in | T39: Cash | U39: Noida
... A57: MM-0056 | B57: 46021 | C57: Floor Cleaner 1L | D57: Household | E57: 8 | F57: 125 | G57: 0.15 | H57: 850 | I57: 0 | J57: 0 | K57: 8 | L57: 850 | M57: 680.69 | N57: 169.31 | O57: =N57/L57 -> 0.19918824 | P57: 48.18 | Q57: 121.13 | R57: =Q57/L57 -> 0.14250588 | S57: New | T57: Card | U57: Gurugram
A58: MM-0057 | B58: 45805 | C58: Soft Drink 750ml | D58: Beverages | E58: 6 | F58: 48 | G58: 0 | H58: 288 | I58: 6 | J58: 288 | K58: 0 | L58: 0 | M58: 0 | N58: 0 | O58: 0 | P58: 0 | Q58: 0 | R58: 0 | S58: Walk-in | T58: Wallet | U58: Delhi
A59: MM-0058 | B59: 45969 | C59: Chocolate Bar | D59: Snacks | E59: 4 | F59: 55 | G59: 0.02 | H59: 215.6 | I59: 0 | J59: 0 | K59: 4 | L59: 215.6 | M59: 145.96 | N59: 69.64 | O59: =N59/L59 -> 0.32300557 | P59: 19.02 | Q59: 50.62 | R59: =Q59/L59 -> 0.23478664 | S59: Regular | T59: UPI | U59: Delhi
A60: MM-0059 | B60: 45870 | C60: Coffee 200g | D60: Beverages | E60: 5 | F60: 180 | G60: 0.15 | H60: 765 | I60: 0 | J60: 0 | K60: 5 | L60: 765 | M60: 576.38 | N60: 188.62 | O60: =N60/L60 -> 0.24656209 | P60: 40.91 | Q60: 147.71 | R60: =Q60/L60 -> 0.19308497 | S60: Member | T60: Wallet | U60: Delhi
A61: MM-0060 | B61: 45658 | C61: Cooking Oil 1L | D61: Groceries | E61: 3 | F61: 145 | G61: 0.15 | H61: 369.75 | I61: 0 | J61: 0 | K61: 3 | L61: 369.75 | M61: 275.66 | N61: 94.09 | O61: =N61/L61 -> 0.25446924 | P61: 39.07 | Q61: 55.02 | R61: =Q61/L61 -> 0.14880325 | S61: Regular | T61: UPI | U61: Noida
A62: MM-0061 | B62: 45813 | C62: Sugar 1kg | D62: Groceries | E62: 6 | F62: 52 | G62: 0 | H62: 312 | I62: 0 | J62: 0 | K62: 6 | L62: 312 | M62: 214.48 | N62: 97.52 | O62: =N62/L62 -> 0.3125641 | P62: 37.82 | Q62: 59.7 | R62: =Q62/L62 -> 0.19134615 | S62: Regular | T62: Wallet | U62: Noida
A63: MM-0062 | B63: 45849 | C63: Cooking Oil 1L | D63: Groceries | E63: 3 | F63: 145 | G63: 0 | H63: 435 | I63: 0 | J63: 0 | K63: 3 | L63: 435 | M63: 330.63 | N63: 104.37 | O63: =N63/L63 -> 0.23993103 | P63: 55.66 | Q63: 48.71 | R63: =Q63/L63 -> 0.11197701 | S63: Member | T63: UPI | U63: Gurugram
A64: MM-0063 | B64: 45692 | C64: Floor Cleaner 1L | D64: Household | E64: 2 | F64: 125 | G64: 0 | H64: 250 | I64: 0 | J64: 0 | K64: 2 | L64: 250 | M64: 191.17 | N64: 58.83 | O64: =N64/L64 -> 0.23532 | P64: 15.16 | Q64: 43.67 | R64: =Q64/L64 -> 0.17468 | S64: Regular | T64: UPI | U64: Noida
A65: MM-0064 | B65: 46022 | C65: Batteries Pack | D65: Electronics | E65: 4 | F65: 85 | G65: 0.02 | H65: 333.2 | I65: 0 | J65: 0 | K65: 4 | L65: 333.2 | M65: 240.03 | N65: 93.17 | O65: =N65/L65 -> 0.27962185 | P65: 39.75 | Q65: 53.42 | R65: =Q65/L65 -> 0.16032413 | S65: Regular | T65: Card | U65: Ghaziabad
A66: MM-0065 | B66: 45874 | C66: Rice 5kg | D66: Groceries | E66: 5 | F66: 420 | G66: 0 | H66: 2100 | I66: 0 | J66: 0 | K66: 5 | L66: 2100 | M66: 1798.58 | N66: 301.42 | O66: =N66/L66 -> 0.14353333 | P66: 230.93 | Q66: 70.49 | R66: =Q66/L66 -> 0.033566667 | S66: New | T66: Card | U66: Gurugram
A67: MM-0066 | B67: 45663 | C67: Floor Cleaner 1L | D67: Household | E67: 5 | F67: 125 | G67: 0 | H67: 625 | I67: 0 | J67: 0 | K67: 5 | L67: 625 | M67: 449.72 | N67: 175.28 | O67: =N67/L67 -> 0.280448 | P67: 34.07 | Q67: 141.21 | R67: =Q67/L67 -> 0.225936 | S67: Walk-in | T67: Cash | U67: Delhi
A68: MM-0067 | B68: 45802 | C68: Tea 250g | D68: Beverages | E68: 10 | F68: 125 | G68: 0.02 | H68: 1225 | I68: 0 | J68: 0 | K68: 10 | L68: 1225 | M68: 985.58 | N68: 239.42 | O68: =N68/L68 -> 0.1954449 | P68: 144.52 | Q68: 94.9 | R68: =Q68/L68 -> 0.077469388 | S68: Regular | T68: UPI | U68: Delhi
A69: MM-0068 | B69: 45691 | C69: Toothpaste 150g | D69: Personal Care | E69: 2 | F69: 110 | G69: 0 | H69: 220 | I69: 0 | J69: 0 | K69: 2 | L69: 220 | M69: 147.34 | N69: 72.66 | O69: =N69/L69 -> 0.33027273 | P69: 24.32 | Q69: 48.34 | R69: =Q69/L69 -> 0.21972727 | S69: Walk-in | T69: Card | U69: Ghaziabad
...

Sheet Dashboard
B1: MEGA MARKET — SALES & PROFIT EXECUTIVE DASHBOARD
B3: Delhi-NCR multi-category retail · FY2025 (Jan–Dec) · All figures are live formulas from the "Cleaned Data" table (Calc sheet) — nothing is hardcoded
B4: FILTERS (choose from each dropdown — every KPI, chart and insight below updates instantly; pick "All" / "Jan"–"Dec" to reset)
B5: Category | F5: City | J5: Customer Type | N5: Payment Method | R5: From month | V5: To month
B6: All | F6: All | J6: All | N6: All | R6: May | V6: Dec
B7: =Calc!$B$153 -> ✔ All reconciliation checks pass — dashboard ties to Cleaned Data
B9: Total Sales (₹) | F9: Net Sales (₹) | J9: Gross Profit (₹) | N9: Net Profit (₹) | R9: Return Rate (units)
B10: =Calc!$B$19 -> 534759.67 | F10: =Calc!$B$21 -> 525460.17 | J10: =Calc!$B$22 -> 136936.28 | N10: =Calc!$B$23 -> 89567.45 | R10: =Calc!$B$31 -> 0.018113385
B13: Gross Profit Margin | F13: Net Profit Margin | J13: Net Qty Sold (units) | N13: Average Order Value (₹) | R13: Sales Return (₹)
B14: =Calc!$B$29 -> 0.26060259 | F14: =Calc!$B$30 -> 0.17045526 | J14: =Calc!$B$26 -> 4174 | N14: =Calc!$B$28 -> 398.07589 | R14: =Calc!$B$20 -> 9299.5
B17: =" "&"Trend ("&INDEX(Calc!$B$37:$B$48,Calc!$C$10)&" vs prior month): Net Sales "&Calc!$F$21&" | Gross Profit "&Calc!$F$22&" | Net Profit "&Calc!$F$23 -> Trend (Dec vs prior month): Net Sales ▲ 17.1% · Dec vs Nov | Gross Profit ▲ 19.0% · Dec vs Nov | Net Profit ▲ 21.8% · Dec vs Nov
B19: MONTHLY TREND & CATEGORY PERFORMANCE
B38: TOP/BOTTOM PRODUCTS & CITY / CUSTOMER / PAYMENT MIX
B57: CITY CONTRIBUTION & CUSTOMER / PAYMENT MIX
B76: RETURNS ANALYSIS

Sheet Insights & Recommendations
B1: MEGA MARKET — KEY INSIGHTS & RECOMMENDATIONS (FY2025)
B2: Figures below are computed live from the "Calc" sheet, which sums the "Cleaned Data" table — nothing here is typed in by hand. Numbers reflect the full-year, all-filters dataset (₹779,939.05 Net Sales) as documented in the Requirements sheet.
B4: 1. SALES & PROFIT DRIVERS
B5: ="Groceries and Household are the clear revenue engines, together contributing "&TEXT((Calc!B54+Calc!B55)/Calc!B61,"0.0%")&" of Net Sales ("&TEXT(Calc!B54,"₹#,##0")&" and "&TEXT(Calc!B55,"₹#,##0")&" respectively). The five hero SKUs — "&Calc!B91&", "&Calc!B92&", "&Calc!B93&", "&Calc!B94&" and "&Calc!B95&" — sit almost entirely inside those two categories, so revenue concentration and category concentration are the same story. Profit follows the same pattern: Groceries also leads on Gross Profit ("&TEXT(Calc!C54,"₹#,##0")&") and Net Profit ("&TEXT(Calc!D54,"₹#,##0")&"), so — unlike a typical retail mix — the top revenue category here is not lagging on margin: its Gross Profit Margin ("&TEXT(Calc!I54,"0.0%")&") is in line with the store-wide average ("&TEXT(Calc!I61,"0.0%")&")." -> Groceries and Household are the clear revenue engines, together contributing 57.7% of Net Sales (₹2,01,364 and ₹1,01,609 respectively). The five hero SKUs — Rice 5kg, Wheat Flour 5kg, Laundry Detergent 2kg, Coffee 200g and Shampoo 340ml — sit almost entirely inside those two categories, so revenue concentration and category concentration are the same story. Profit follows the same pattern: Groceries also leads on Gross Profit (₹53,116) and Net Profit (₹34,797), so — unlike a typical retail mix — the top revenue category here is not lagging on margin: its Gross Profit Margin (26.4%) is in line with the store-wide average (26.1%).
B6: ="Ghaziabad and Delhi are the top two cities by Net Sales ("&TEXT(Calc!B100,"₹#,##0")&" and "&TEXT(Calc!B101,"₹#,##0")&"), but all four named cities are within "&TEXT((Calc!B100-Calc!B103)/Calc!B100,"0.0%")&" of each other — city is not a strong differentiator this year, unlike category or product. Customer Type and Payment Method are similarly balanced, each real segment holding roughly "&TEXT(Calc!B110/Calc!B115,"0%")&"–"&TEXT(Calc!B112/Calc!B115,"0%")&" of Net Sales — no single acquisition channel or payment rail is over- or under-performing enough to flag." -> Ghaziabad and Delhi are the top two cities by Net Sales (₹1,36,753 and ₹1,34,972), but all four named cities are within 10.0% of each other — city is not a strong differentiator this year, unlike category or product. Customer Type and Payment Method are similarly balanced, each real segment holding roughly 24%–25% of Net Sales — no single acquisition channel or payment rail is over- or under-performing enough to flag.
B7: 2. WEAK PERFORMERS
B8: ="The lowest-revenue products are "&Calc!D91&" ("&TEXT(Calc!E91,"₹#,##0")&"), "&Calc!D92&" ("&TEXT(Calc!E92,"₹#,##0")&") and "&Calc!D93&" ("&TEXT(Calc!E93,"₹#,##0")&") — all everyday, low-unit-price items where volume has not compensated for low price. By category, Stationery is the clear laggard: only "&TEXT(Calc!B60/Calc!B61,"0.0%")&" of Net Sales and the lowest absolute Gross Profit ("&TEXT(Calc!C60,"₹#,##0")&") of any category, alongside Snacks (also under 5% of sales). Margins across categories are otherwise tight, within a "&TEXT(MIN(Calc!I54:I60),"0.0%")&"–"&TEXT(MAX(Calc!I54:I60),"0.0%")&" Gross Profit Margin band, so no category is a structural margin problem — the issue for the weak categories is sales volume, not pricing." -> The lowest-revenue products are Mineral Water 1L (₹3,398), Potato Chips (₹6,233) and Biscuits Pack (₹7,640) — all everyday, low-unit-price items where volume has not compensated for low price. By category, Stationery is the clear laggard: only 1.8% of Net Sales and the lowest absolute Gross Profit (₹2,436) of any category, alongside Snacks (also under 5% of sales). Margins across categories are otherwise tight, within a 24.8%–27.0% Gross Profit Margin band, so no category is a structural margin problem — the issue for the weak categories is sales volume, not pricing.
B9: A genuine data-quality gap sits in three fields: 20 rows (Customer Type), 15 rows (Payment Method) and 12 rows (City) are recorded as 'Unknown' — small in absolute terms (well under 1% of the 2,000 invoices each) but concentrated at checkout, meaning the gap is operational (a step being skipped) rather than random. These rows are retained as 'Unknown' rather than guessed, per the cleaning log on the Quality Checks sheet, so they remain visible here rather than silently disappearing from the analysis.
B10: 3. TREND TAKEAWAYS
B11: ="Monthly Net Sales ranges from "&TEXT(MIN(Calc!G37:G48),"₹#,##0")&" to "&TEXT(MAX(Calc!G37:G48),"₹#,##0")&". "&INDEX(Calc!B37:B48,MATCH(MAX(Calc!G37:G48),Calc!G37:G48,0))&" is the peak month and "&INDEX(Calc!B37:B48,MATCH(MIN(Calc!G37:G48),Calc!G37:G48,0))&" the weakest, with no single run of consecutive slow months — the year reads as noisy month-to-month rather than a seasonal decline. Net Profit Margin is essentially flat across the year: H1 (Jan–Jun) averages "&TEXT(SUMIFS(d_NP,d_Date,">="&DATE(Calc!$C$11,1,1),d_Date,"<="&DATE(Calc!$C$11,6,30))/SUMIFS(d_NetSales,d_Date,">="&DATE(Calc!$C$11,1,1),d_Date,"<="&DATE(Calc!$C$11,6,30)),"0.0%")&" against H2's (Jul–Dec) "&TEXT(SUMIFS(d_NP,d_Date,">="&DATE(Calc!$C$11,7,1),d_Date,"<="&DATE(Calc!$C$11,12,31))/SUMIFS(d_NetSales,d_Date,">="&DATE(Calc!$C$11,7,1),d_Date,"<="&DATE(Calc!$C$11,12,31)),"0.0%")&", a gap of well under one percentage point — a trend to keep monitoring, not one requiring immediate action." -> Monthly Net Sales ranges from ₹53,367 to ₹79,101. Aug is the peak month and Feb the weakest, with no single run of consecutive slow months — the year reads as noisy month-to-month rather than a seasonal decline. Net Profit Margin is essentially flat across the year: H1 (Jan–Jun) averages 16.8% against H2's (Jul–Dec) 17.1%, a gap of well under one percentage point — a trend to keep monitoring, not one requiring immediate action.
B12: 4. RETURNS
B13: ="Overall Return Rate is "&TEXT(Calc!B31,"0.0%")&" of units ("&Calc!B25&" of "&TEXT(Calc!B24,"#,##0")&"), worth "&TEXT(Calc!B20,"₹#,##0")&" in returned sales value — a healthy level for retail. Snacks and Groceries carry the highest absolute Return Qty, but scaled to their own sales volume the picture flips: Stationery has the highest true Return Rate at "&TEXT(MAX(Calc!K54:K60),"0.0%")&" of its units, more than double the store-wide rate, while Groceries' rate ("&TEXT(Calc!K54,"0.0%")&") is close to average — so its high return count is simply proportional to being the best-selling category, not a genuine quality issue. Stationery is the one category where returns deserve a root-cause look." -> Overall Return Rate is 1.8% of units (77 of 4,251), worth ₹9,300 in returned sales value — a healthy level for retail. Snacks and Groceries carry the highest absolute Return Qty, but scaled to their own sales volume the picture flips: Stationery has the highest true Return Rate at 3.0% of its units, more than double the store-wide rate, while Groceries' rate (2.1%) is close to average — so its high return count is simply proportional to being the best-selling category, not a genuine quality issue. Stationery is the one category where returns deserve a root-cause look.
B14: 5. RECOMMENDATIONS
B15: • Protect and extend the Groceries/Household hero SKUs (Rice 5kg, Wheat Flour 5kg, Laundry Detergent 2kg, Coffee 200g, Shampoo 340ml): prioritise these for stock cover and end-of-aisle promotion, since they already anchor both revenue and profit.
B16: • Give Stationery and Snacks a defined promotional and merchandising push (bundle offers, cross-placement near Groceries) — their margins are normal, so the fix is demand, not price.
B17: • Investigate Stationery returns specifically: its Return Rate is the highest of any category despite modest sales, which points to a quality, sizing, or expectation-mismatch issue worth a root-cause review rather than a blanket discount cut.
B18: • Tighten checkout data capture for Customer Type, Payment Method and City — even a short mandatory prompt at the till would close the "Unknown" gap and materially improve segment-level targeting.
B19: • Keep discounting concentrated where it already performs (0% and 10-15% bands show the healthiest margins in the Cleaned Data); review the 2-6% discount band, whose margin sits slightly below the other bands for no clear return in volume.
B20: • Watch Net Profit Margin monthly rather than only annually — it is flat year-over-year in aggregate, but the Dashboard's month filter should be used at each business review to catch any emerging dip early.
B22: ASSUMPTIONS & DATA NOTES (also see "Quality Checks" sheet)
B23: • Blank Customer Type, Payment Method and City values were retained as "Unknown" rather than guessed, per the original cleaning log — they remain visible in every chart and KPI (never filtered out silently).
B24: • Net Sales (₹) — after returns — is used as the primary revenue metric throughout this dashboard, per the brief; "Total Sales" is shown separately as the pre-return gross figure.
B25: • Every figure on the Dashboard and in this sheet is a live formula referencing the "Cleaned Data" table via the "Calc" sheet — see the reconciliation checks at the bottom of "Calc" (section 11), which confirm every total ties back to "Cleaned Data" to the rupee.

Sheet Quality Checks
A1: Mega Market — Data Quality & Cleaning Summary
A2: Check | B2: Result
A3: Original transaction rows | B3: 2002
A4: Exact duplicate rows removed | B4: 2
A5: Cleaned transaction rows | B5: 2000
A6: Missing Customer Type handled | B6: 0
A7: Missing Payment Method handled | B7: 0
A8: Missing City handled | B8: 0
A9: Financial calculation mismatches | B9: 0
A10: Quantity/return validation issues | B10: 0
A11: Date format | B11: dd-mmm-yyyy
A12: Currency format | B12: ₹#,##0 (no decimals)
A13: Discount format | B13: 0% (converted from whole percentage points)
A15: Missing-value treatment
A16: Blank Customer Type, Payment Method, and City values were retained as 'Unknown' rather than guessed.

Sheet Calc
A1: Calc — formula layer feeding the Dashboard (replaces PivotTables; every value is a live formula on "Cleaned Data")
A2: All blocks respond to the Dashboard dropdowns. Named ranges d_* point at the "Cleaned Data" table columns; fCat/fCity/fCust/fPay/fStart/fEnd are the active filter criteria ("*" = all).
A4: 1. FILTER CRITERIA (linked to Dashboard dropdowns) | F4: Dropdown lists → Category | City | Customer | Payment | Month
A5: Category | B5: =Dashboard!$B$6 -> All | C5: =IF(B5="All","*",B5) -> * | F5: All | G5: All | H5: All | I5: All | J5: Jan
A6: City | B6: =Dashboard!$F$6 -> All | C6: =IF(B6="All","*",B6) -> * | F6: Groceries | G6: Ghaziabad | H6: Member | I6: Card | J6: Feb
A7: Customer Type | B7: =Dashboard!$J$6 -> All | C7: =IF(B7="All","*",B7) -> * | F7: Household | G7: Delhi | H7: Regular | I7: Cash | J7: Mar
A8: Payment Method | B8: =Dashboard!$N$6 -> All | C8: =IF(B8="All","*",B8) -> * | F8: Beverages | G8: Noida | H8: New | I8: UPI | J8: Apr
A9: From month | B9: =Dashboard!$R$6 -> May | C9: =IFERROR(MATCH(B9,$J$5:$J$16,0),1) -> 5 | F9: Personal Care | G9: Gurugram | H9: Walk-in | I9: Wallet | J9: May
A10: To month | B10: =Dashboard!$V$6 -> Dec | C10: =IFERROR(MATCH(B10,$J$5:$J$16,0),12) -> 12 | F10: Electronics | G10: Unknown | H10: Unknown | I10: Unknown | J10: Jun
A11: Data year | C11: =YEAR(MIN(d_Date)) -> 2025 | F11: Snacks | J11: Jul
A12: Period start date | C12: =DATE(C11,C9,1) -> 45778 | F12: Stationery | J12: Aug
A13: Period end date | C13: =EOMONTH(DATE(C11,C10,1),0) -> 46022 | J13: Sep
A14: Filters at default (All / Jan–Dec)? | C14: =IF(AND(B5="All",B6="All",B7="All",B8="All",C9=1,C10=12),1,0) -> 0 | J14: Oct
J15: Nov
J16: Dec
A17: 2. KPI SUMMARY (all filters applied, incl. period) + month-over-month (To-month vs prior month)
A18: Metric | B18: Value | C18: To-month value | D18: Prior-month value | E18: Change | F18: Indicator text
A19: Total Sales (₹) — gross | B19: =SUMIFS(d_Sales,d_Category,fCat,d_City,fCity,d_Cust,fCust,d_Pay,fPay,d_Date,">="&fStart,d_Date,"<="&fEnd) -> 534759.67 | C19: =INDEX($E$37:$E$48,$C$10) -> 64278.95 | D19: =IF($C$10>1,INDEX($E$37:$E$48,$C$10-1),"") -> 54697.53 | E19: =IF(AND(ISNUMBER(D19),D19<>0),(C19-D19)/D19,"") -> 0.17517098 | F19: =IF(E19="","— no prior month",IF(E19>=0,"▲ ","▼ ")&TEXT(ABS(E19),"0.0%")&" · "&INDEX($B$37:$B$48,$C$10)&" vs "&INDEX($B$37:$B$48,$C$10-1)) -> ▲ 17.5% · Dec vs Nov
A20: Sales Return (₹) | B20: =SUMIFS(d_SalesRet,d_Category,fCat,d_City,fCity,d_Cust,fCust,d_Pay,fPay,d_Date,">="&fStart,d_Date,"<="&fEnd) -> 9299.5 | C20: =INDEX($F$37:$F$48,$C$10) -> 1660 | D20: =IF($C$10>1,INDEX($F$37:$F$48,$C$10-1),"") -> 1201.9 | E20: =IF(AND(ISNUMBER(D20),D20<>0),(C20-D20)/D20,"") -> 0.38114652 | F20: =IF(E20="","— no prior month",IF(E20>=0,"▲ ","▼ ")&TEXT(ABS(E20),"0.0%")&" · "&INDEX($B$37:$B$48,$C$10)&" vs "&INDEX($B$37:$B$48,$C$10-1)) -> ▲ 38.1% · Dec vs Nov
A21: Net Sales (₹) | B21: =SUMIFS(d_NetSales,d_Category,fCat,d_City,fCity,d_Cust,fCust,d_Pay,fPay,d_Date,">="&fStart,d_Date,"<="&fEnd) -> 525460.17 | C21: =INDEX($G$37:$G$48,$C$10) -> 62618.95 | D21: =IF($C$10>1,INDEX($G$37:$G$48,$C$10-1),"") -> 53495.63 | E21: =IF(AND(ISNUMBER(D21),D21<>0),(C21-D21)/D21,"") -> 0.17054328 | F21: =IF(E21="","— no prior month",IF(E21>=0,"▲ ","▼ ")&TEXT(ABS(E21),"0.0%")&" · "&INDEX($B$37:$B$48,$C$10)&" vs "&INDEX($B$37:$B$48,$C$10-1)) -> ▲ 17.1% · Dec vs Nov
A22: Gross Profit (₹) | B22: =SUMIFS(d_GP,d_Category,fCat,d_City,fCity,d_Cust,fCust,d_Pay,fPay,d_Date,">="&fStart,d_Date,"<="&fEnd) -> 136936.28 | C22: =INDEX($H$37:$H$48,$C$10) -> 16403.21 | D22: =IF($C$10>1,INDEX($H$37:$H$48,$C$10-1),"") -> 13783.7 | E22: =IF(AND(ISNUMBER(D22),D22<>0),(C22-D22)/D22,"") -> 0.19004404 | F22: =IF(E22="","— no prior month",IF(E22>=0,"▲ ","▼ ")&TEXT(ABS(E22),"0.0%")&" · "&INDEX($B$37:$B$48,$C$10)&" vs "&INDEX($B$37:$B$48,$C$10-1)) -> ▲ 19.0% · Dec vs Nov
A23: Net Profit (₹) | B23: =SUMIFS(d_NP,d_Category,fCat,d_City,fCity,d_Cust,fCust,d_Pay,fPay,d_Date,">="&fStart,d_Date,"<="&fEnd) -> 89567.45 | C23: =INDEX($I$37:$I$48,$C$10) -> 10760.4 | D23: =IF($C$10>1,INDEX($I$37:$I$48,$C$10-1),"") -> 8836.61 | E23: =IF(AND(ISNUMBER(D23),D23<>0),(C23-D23)/D23,"") -> 0.21770679 | F23: =IF(E23="","— no prior month",IF(E23>=0,"▲ ","▼ ")&TEXT(ABS(E23),"0.0%")&" · "&INDEX($B$37:$B$48,$C$10)&" vs "&INDEX($B$37:$B$48,$C$10-1)) -> ▲ 21.8% · Dec vs Nov
A24: Total Quantity Sold (gross units) | B24: =SUMIFS(d_Qty,d_Category,fCat,d_City,fCity,d_Cust,fCust,d_Pay,fPay,d_Date,">="&fStart,d_Date,"<="&fEnd) -> 4251 | C24: =INDEX($J$37:$J$48,$C$10) -> 564 | D24: =IF($C$10>1,INDEX($J$37:$J$48,$C$10-1),"") -> 495 | E24: =IF(AND(ISNUMBER(D24),D24<>0),(C24-D24)/D24,"") -> 0.13939394 | F24: =IF(E24="","— no prior month",IF(E24>=0,"▲ ","▼ ")&TEXT(ABS(E24),"0.0%")&" · "&INDEX($B$37:$B$48,$C$10)&" vs "&INDEX($B$37:$B$48,$C$10-1)) -> ▲ 13.9% · Dec vs Nov
A25: Return Qty (units) | B25: =SUMIFS(d_RetQty,d_Category,fCat,d_City,fCity,d_Cust,fCust,d_Pay,fPay,d_Date,">="&fStart,d_Date,"<="&fEnd) -> 77 | C25: =INDEX($K$37:$K$48,$C$10) -> 11 | D25: =IF($C$10>1,INDEX($K$37:$K$48,$C$10-1),"") -> 7 | E25: =IF(AND(ISNUMBER(D25),D25<>0),(C25-D25)/D25,"") -> 0.57142857 | F25: =IF(E25="","— no prior month",IF(E25>=0,"▲ ","▼ ")&TEXT(ABS(E25),"0.0%")&" · "&INDEX($B$37:$B$48,$C$10)&" vs "&INDEX($B$37:$B$48,$C$10-1)) -> ▲ 57.1% · Dec vs Nov
A26: Net Quantity Sold (units) | B26: =SUMIFS(d_NetQty,d_Category,fCat,d_City,fCity,d_Cust,fCust,d_Pay,fPay,d_Date,">="&fStart,d_Date,"<="&fEnd) -> 4174 | C26: =INDEX($L$37:$L$48,$C$10) -> 553 | D26: =IF($C$10>1,INDEX($L$37:$L$48,$C$10-1),"") -> 488 | E26: =IF(AND(ISNUMBER(D26),D26<>0),(C26-D26)/D26,"") -> 0.13319672 | F26: =IF(E26="","— no prior month",IF(E26>=0,"▲ ","▼ ")&TEXT(ABS(E26),"0.0%")&" · "&INDEX($B$37:$B$48,$C$10)&" vs "&INDEX($B$37:$B$48,$C$10-1)) -> ▲ 13.3% · Dec vs Nov
A27: Invoices (distinct Invoice IDs) | B27: =COUNTIFS(d_Category,fCat,d_City,fCity,d_Cust,fCust,d_Pay,fPay,d_Date,">="&fStart,d_Date,"<="&fEnd) -> 1320 | C27: =INDEX($M$37:$M$48,$C$10) -> 167 | D27: =IF($C$10>1,INDEX($M$37:$M$48,$C$10-1),"") -> 160 | E27: =IF(AND(ISNUMBER(D27),D27<>0),(C27-D27)/D27,"") -> 0.04375 | F27: =IF(E27="","— no prior month",IF(E27>=0,"▲ ","▼ ")&TEXT(ABS(E27),"0.0%")&" · "&INDEX($B$37:$B$48,$C$10)&" vs "&INDEX($B$37:$B$48,$C$10-1)) -> ▲ 4.4% · Dec vs Nov
A28: Average Order Value (₹) | B28: =IF(B27=0,0,B21/B27) -> 398.07589 | C28: =INDEX($Q$37:$Q$48,$C$10) -> 374.96377 | D28: =IF($C$10>1,INDEX($Q$37:$Q$48,$C$10-1),"") -> 334.34769 | E28: =IF(AND(ISNUMBER(D28),D28<>0),(C28-D28)/D28,"") -> 0.12147859 | F28: =IF(E28="","— no prior month",IF(E28>=0,"▲ ","▼ ")&TEXT(ABS(E28),"0.0%")&" · "&INDEX($B$37:$B$48,$C$10)&" vs "&INDEX($B$37:$B$48,$C$10-1)) -> ▲ 12.1% · Dec vs Nov
A29: Gross Profit Margin | B29: =IF(B21=0,0,B22/B21) -> 0.26060259 | C29: =INDEX($N$37:$N$48,$C$10) -> 0.26195281 | D29: =IF($C$10>1,INDEX($N$37:$N$48,$C$10-1),"") -> 0.2576603 | E29: =IF(ISNUMBER(D29),C29-D29,"") -> 0.0042925128 | F29: =IF(E29="","— no prior month",IF(E29>=0,"▲ ","▼ ")&TEXT(ABS(E29)*100,"0.0")&" pp · "&INDEX($B$37:$B$48,$C$10)&" vs "&INDEX($B$37:$B$48,$C$10-1)) -> ▲ 0.4 pp · Dec vs Nov
A30: Net Profit Margin | B30: =IF(B21=0,0,B23/B21) -> 0.17045526 | C30: =INDEX($O$37:$O$48,$C$10) -> 0.17183936 | D30: =IF($C$10>1,INDEX($O$37:$O$48,$C$10-1),"") -> 0.16518377 | E30: =IF(ISNUMBER(D30),C30-D30,"") -> 0.0066555824 | F30: =IF(E30="","— no prior month",IF(E30>=0,"▲ ","▼ ")&TEXT(ABS(E30)*100,"0.0")&" pp · "&INDEX($B$37:$B$48,$C$10)&" vs "&INDEX($B$37:$B$48,$C$10-1)) -> ▲ 0.7 pp · Dec vs Nov
A31: Return Rate (Return Qty ÷ Qty) | B31: =IF(B24=0,0,B25/B24) -> 0.018113385 | C31: =INDEX($P$37:$P$48,$C$10) -> 0.019503546 | D31: =IF($C$10>1,INDEX($P$37:$P$48,$C$10-1),"") -> 0.014141414 | E31: =IF(ISNUMBER(D31),C31-D31,"") -> 0.005362132 | F31: =IF(E31="","— no prior month",IF(E31>=0,"▲ ","▼ ")&TEXT(ABS(E31)*100,"0.0")&" pp · "&INDEX($B$37:$B$48,$C$10)&" vs "&INDEX($B$37:$B$48,$C$10-1)) -> ▲ 0.5 pp · Dec vs Nov
A35: 3. MONTHLY (all filters EXCEPT the period — always Jan–Dec so the trend context is visible)
A36: Month # | B36: Month | C36: Start | D36: End | E36: Total Sales (₹) | F36: Sales Return (₹) | G36: Net Sales (₹) | H36: Gross Profit (₹) | I36: Net Profit (₹) | J36: Qty | K36: Return Qty | L36: Net Qty | M36: Invoices | N36: GP Margin | O36: NP Margin | P36: Return Rate (Qty) | Q36: Avg Order Value (₹) | R36: Key: weakest month
A37: 1 | B37: Jan | C37: =DATE($C$11,A37,1) -> 45658 | D37: =EOMONTH(C37,0) -> 45688 | E37: =SUMIFS(d_Sales,d_Category,fCat,d_City,fCity,d_Cust,fCust,d_Pay,fPay,d_Date,">="&$C37,d_Date,"<="&$D37) -> 71958.47 | F37: =SUMIFS(d_SalesRet,d_Category,fCat,d_City,fCity,d_Cust,fCust,d_Pay,fPay,d_Date,">="&$C37,d_Date,"<="&$D37) -> 1375 | G37: =SUMIFS(d_NetSales,d_Category,fCat,d_City,fCity,d_Cust,fCust,d_Pay,fPay,d_Date,">="&$C37,d_Date,"<="&$D37) -> 70583.47 | H37: =SUMIFS(d_GP,d_Category,fCat,d_City,fCity,d_Cust,fCust,d_Pay,fPay,d_Date,">="&$C37,d_Date,"<="&$D37) -> 18094.27 | I37: =SUMIFS(d_NP,d_Category,fCat,d_City,fCity,d_Cust,fCust,d_Pay,fPay,d_Date,">="&$C37,d_Date,"<="&$D37) -> 11832.23 | J37: =SUMIFS(d_Qty,d_Category,fCat,d_City,fCity,d_Cust,fCust,d_Pay,fPay,d_Date,">="&$C37,d_Date,"<="&$D37) -> 556 | K37: =SUMIFS(d_RetQty,d_Category,fCat,d_City,fCity,d_Cust,fCust,d_Pay,fPay,d_Date,">="&$C37,d_Date,"<="&$D37) -> 5 | L37: =SUMIFS(d_NetQty,d_Category,fCat,d_City,fCity,d_Cust,fCust,d_Pay,fPay,d_Date,">="&$C37,d_Date,"<="&$D37) -> 551 | M37: =COUNTIFS(d_Category,fCat,d_City,fCity,d_Cust,fCust,d_Pay,fPay,d_Date,">="&$C37,d_Date,"<="&$D37) -> 166 | N37: =IF(G37=0,0,H37/G37) -> 0.2563528 | O37: =IF(G37=0,0,I37/G37) -> 0.16763458 | P37: =IF(J37=0,0,K37/J37) -> 0.0089928058 | Q37: =IF(M37=0,0,G37/M37) -> 425.20163 | R37: =IF(G37>0,G37,1E+99) -> 70583.47
A38: 2 | B38: Feb | C38: =DATE($C$11,A38,1) -> 45689 | D38: =EOMONTH(C38,0) -> 45716 | E38: =SUMIFS(d_Sales,d_Category,fCat,d_City,fCity,d_Cust,fCust,d_Pay,fPay,d_Date,">="&$C38,d_Date,"<="&$D38) -> 53988.62 | F38: =SUMIFS(d_SalesRet,d_Category,fCat,d_City,fCity,d_Cust,fCust,d_Pay,fPay,d_Date,">="&$C38,d_Date,"<="&$D38) -> 621.64 | G38: =SUMIFS(d_NetSales,d_Category,fCat,d_City,fCity,d_Cust,fCust,d_Pay,fPay,d_Date,">="&$C38,d_Date,"<="&$D38) -> 53366.98 | H38: =SUMIFS(d_GP,d_Category,fCat,d_City,fCity,d_Cust,fCust,d_Pay,fPay,d_Date,">="&$C38,d_Date,"<="&$D38) -> 13968.5 | I38: =SUMIFS(d_NP,d_Category,fCat,d_City,fCity,d_Cust,fCust,d_Pay,fPay,d_Date,">="&$C38,d_Date,"<="&$D38) -> 9247.88 | J38: =SUMIFS(d_Qty,d_Category,fCat,d_City,fCity,d_Cust,fCust,d_Pay,fPay,d_Date,">="&$C38,d_Date,"<="&$D38) -> 514 | K38: =SUMIFS(d_RetQty,d_Category,fCat,d_City,fCity,d_Cust,fCust,d_Pay,fPay,d_Date,">="&$C38,d_Date,"<="&$D38) -> 8 | L38: =SUMIFS(d_NetQty,d_Category,fCat,d_City,fCity,d_Cust,fCust,d_Pay,fPay,d_Date,">="&$C38,d_Date,"<="&$D38) -> 506 | M38: =COUNTIFS(d_Category,fCat,d_City,fCity,d_Cust,fCust,d_Pay,fPay,d_Date,">="&$C38,d_Date,"<="&$D38) -> 160 | N38: =IF(G38=0,0,H38/G38) -> 0.26174425 | O38: =IF(G38=0,0,I38/G38) -> 0.17328843 | P38: =IF(J38=0,0,K38/J38) -> 0.015564202 | Q38: =IF(M38=0,0,G38/M38) -> 333.54362 | R38: =IF(G38>0,G38,1E+99) -> 53366.98
A39: 3 | B39: Mar | C39: =DATE($C$11,A39,1) -> 45717 | D39: =EOMONTH(C39,0) -> 45747 | E39: =SUMIFS(d_Sales,d_Category,fCat,d_City,fCity,d_Cust,fCust,d_Pay,fPay,d_Date,">="&$C39,d_Date,"<="&$D39) -> 70833.49 | F39: =SUMIFS(d_SalesRet,d_Category,fCat,d_City,fCity,d_Cust,fCust,d_Pay,fPay,d_Date,">="&$C39,d_Date,"<="&$D39) -> 674 | G39: =SUMIFS(d_NetSales,d_Category,fCat,d_City,fCity,d_Cust,fCust,d_Pay,fPay,d_Date,">="&$C39,d_Date,"<="&$D39) -> 70159.49 | H39: =SUMIFS(d_GP,d_Category,fCat,d_City,fCity,d_Cust,fCust,d_Pay,fPay,d_Date,">="&$C39,d_Date,"<="&$D39) -> 17819.07 | I39: =SUMIFS(d_NP,d_Category,fCat,d_City,fCity,d_Cust,fCust,d_Pay,fPay,d_Date,">="&$C39,d_Date,"<="&$D39) -> 11568.42 | J39: =SUMIFS(d_Qty,d_Category,fCat,d_City,fCity,d_Cust,fCust,d_Pay,fPay,d_Date,">="&$C39,d_Date,"<="&$D39) -> 594 | K39: =SUMIFS(d_RetQty,d_Category,fCat,d_City,fCity,d_Cust,fCust,d_Pay,fPay,d_Date,">="&$C39,d_Date,"<="&$D39) -> 6 | L39: =SUMIFS(d_NetQty,d_Category,fCat,d_City,fCity,d_Cust,fCust,d_Pay,fPay,d_Date,">="&$C39,d_Date,"<="&$D39) -> 588 | M39: =COUNTIFS(d_Category,fCat,d_City,fCity,d_Cust,fCust,d_Pay,fPay,d_Date,">="&$C39,d_Date,"<="&$D39) -> 183 | N39: =IF(G39=0,0,H39/G39) -> 0.25397947 | O39: =IF(G39=0,0,I39/G39) -> 0.16488746 | P39: =IF(J39=0,0,K39/J39) -> 0.01010101 | Q39: =IF(M39=0,0,G39/M39) -> 383.38519 | R39: =IF(G39>0,G39,1E+99) -> 70159.49
A40: 4 | B40: Apr | C40: =DATE($C$11,A40,1) -> 45748 | D40: =EOMONTH(C40,0) -> 45777 | E40: =SUMIFS(d_Sales,d_Category,fCat,d_City,fCity,d_Cust,fCust,d_Pay,fPay,d_Date,">="&$C40,d_Date,"<="&$D40) -> 62206.54 | F40: =SUMIFS(d_SalesRet,d_Category,fCat,d_City,fCity,d_Cust,fCust,d_Pay,fPay,d_Date,">="&$C40,d_Date,"<="&$D40) -> 1837.6 | G40: =SUMIFS(d_NetSales,d_Category,fCat,d_City,fCity,d_Cust,fCust,d_Pay,fPay,d_Date,">="&$C40,d_Date,"<="&$D40) -> 60368.94 | H40: =SUMIFS(d_GP,d_Category,fCat,d_City,fCity,d_Cust,fCust,d_Pay,fPay,d_Date,">="&$C40,d_Date,"<="&$D40) -> 15471.46 | I40: =SUMIFS(d_NP,d_Category,fCat,d_City,fCity,d_Cust,fCust,d_Pay,fPay,d_Date,">="&$C40,d_Date,"<="&$D40) -> 10106.41 | J40: =SUMIFS(d_Qty,d_Category,fCat,d_City,fCity,d_Cust,fCust,d_Pay,fPay,d_Date,">="&$C40,d_Date,"<="&$D40) -> 555 | K40: =SUMIFS(d_RetQty,d_Category,fCat,d_City,fCity,d_Cust,fCust,d_Pay,fPay,d_Date,">="&$C40,d_Date,"<="&$D40) -> 18 | L40: =SUMIFS(d_NetQty,d_Category,fCat,d_City,fCity,d_Cust,fCust,d_Pay,fPay,d_Date,">="&$C40,d_Date,"<="&$D40) -> 537 | M40: =COUNTIFS(d_Category,fCat,d_City,fCity,d_Cust,fCust,d_Pay,fPay,d_Date,">="&$C40,d_Date,"<="&$D40) -> 171 | N40: =IF(G40=0,0,H40/G40) -> 0.25628179 | O40: =IF(G40=0,0,I40/G40) -> 0.16741076 | P40: =IF(J40=0,0,K40/J40) -> 0.032432432 | Q40: =IF(M40=0,0,G40/M40) -> 353.03474 | R40: =IF(G40>0,G40,1E+99) -> 60368.94
A41: 5 | B41: May | C41: =DATE($C$11,A41,1) -> 45778 | D41: =EOMONTH(C41,0) -> 45808 | E41: =SUMIFS(d_Sales,d_Category,fCat,d_City,fCity,d_Cust,fCust,d_Pay,fPay,d_Date,">="&$C41,d_Date,"<="&$D41) -> 76020.12 | F41: =SUMIFS(d_SalesRet,d_Category,fCat,d_City,fCity,d_Cust,fCust,d_Pay,fPay,d_Date,">="&$C41,d_Date,"<="&$D41) -> 2444.9 | G41: =SUMIFS(d_NetSales,d_Category,fCat,d_City,fCity,d_Cust,fCust,d_Pay,fPay,d_Date,">="&$C41,d_Date,"<="&$D41) -> 73575.22 | H41: =SUMIFS(d_GP,d_Category,fCat,d_City,fCity,d_Cust,fCust,d_Pay,fPay,d_Date,">="&$C41,d_Date,"<="&$D41) -> 19322.34 | I41: =SUMIFS(d_NP,d_Category,fCat,d_City,fCity,d_Cust,fCust,d_Pay,fPay,d_Date,">="&$C41,d_Date,"<="&$D41) -> 12855.67 | J41: =SUMIFS(d_Qty,d_Category,fCat,d_City,fCity,d_Cust,fCust,d_Pay,fPay,d_Date,">="&$C41,d_Date,"<="&$D41) -> 535 | K41: =SUMIFS(d_RetQty,d_Category,fCat,d_City,fCity,d_Cust,fCust,d_Pay,fPay,d_Date,">="&$C41,d_Date,"<="&$D41) -> 16 | L41: =SUMIFS(d_NetQty,d_Category,fCat,d_City,fCity,d_Cust,fCust,d_Pay,fPay,d_Date,">="&$C41,d_Date,"<="&$D41) -> 519 | M41: =COUNTIFS(d_Category,fCat,d_City,fCity,d_Cust,fCust,d_Pay,fPay,d_Date,">="&$C41,d_Date,"<="&$D41) -> 168 | N41: =IF(G41=0,0,H41/G41) -> 0.26262021 | O41: =IF(G41=0,0,I41/G41) -> 0.17472826 | P41: =IF(J41=0,0,K41/J41) -> 0.029906542 | Q41: =IF(M41=0,0,G41/M41) -> 437.94774 | R41: =IF(G41>0,G41,1E+99) -> 73575.22
A42: 6 | B42: Jun | C42: =DATE($C$11,A42,1) -> 45809 | D42: =EOMONTH(C42,0) -> 45838 | E42: =SUMIFS(d_Sales,d_Category,fCat,d_City,fCity,d_Cust,fCust,d_Pay,fPay,d_Date,">="&$C42,d_Date,"<="&$D42) -> 56504.39 | F42: =SUMIFS(d_SalesRet,d_Category,fCat,d_City,fCity,d_Cust,fCust,d_Pay,fPay,d_Date,">="&$C42,d_Date,"<="&$D42) -> 112.5 | G42: =SUMIFS(d_NetSales,d_Category,fCat,d_City,fCity,d_Cust,fCust,d_Pay,fPay,d_Date,">="&$C42,d_Date,"<="&$D42) -> 56391.89 | H42: =SUMIFS(d_GP,d_Category,fCat,d_City,fCity,d_Cust,fCust,d_Pay,fPay,d_Date,">="&$C42,d_Date,"<="&$D42) -> 14085.3 | I42: =SUMIFS(d_NP,d_Category,fCat,d_City,fCity,d_Cust,fCust,d_Pay,fPay,d_Date,">="&$C42,d_Date,"<="&$D42) -> 8930.58 | J42: =SUMIFS(d_Qty,d_Category,fCat,d_City,fCity,d_Cust,fCust,d_Pay,fPay,d_Date,">="&$C42,d_Date,"<="&$D42) -> 493 | K42: =SUMIFS(d_RetQty,d_Category,fCat,d_City,fCity,d_Cust,fCust,d_Pay,fPay,d_Date,">="&$C42,d_Date,"<="&$D42) -> 1 | L42: =SUMIFS(d_NetQty,d_Category,fCat,d_City,fCity,d_Cust,fCust,d_Pay,fPay,d_Date,">="&$C42,d_Date,"<="&$D42) -> 492 | M42: =COUNTIFS(d_Category,fCat,d_City,fCity,d_Cust,fCust,d_Pay,fPay,d_Date,">="&$C42,d_Date,"<="&$D42) -> 150 | N42: =IF(G42=0,0,H42/G42) -> 0.24977528 | O42: =IF(G42=0,0,I42/G42) -> 0.15836639 | P42: =IF(J42=0,0,K42/J42) -> 0.0020283976 | Q42: =IF(M42=0,0,G42/M42) -> 375.94593 | R42: =IF(G42>0,G42,1E+99) -> 56391.89
A43: 7 | B43: Jul | C43: =DATE($C$11,A43,1) -> 45839 | D43: =EOMONTH(C43,0) -> 45869 | E43: =SUMIFS(d_Sales,d_Category,fCat,d_City,fCity,d_Cust,fCust,d_Pay,fPay,d_Date,">="&$C43,d_Date,"<="&$D43) -> 65915.22 | F43: =SUMIFS(d_SalesRet,d_Category,fCat,d_City,fCity,d_Cust,fCust,d_Pay,fPay,d_Date,">="&$C43,d_Date,"<="&$D43) -> 1177.25 | G43: =SUMIFS(d_NetSales,d_Category,fCat,d_City,fCity,d_Cust,fCust,d_Pay,fPay,d_Date,">="&$C43,d_Date,"<="&$D43) -> 64737.97 | H43: =SUMIFS(d_GP,d_Category,fCat,d_City,fCity,d_Cust,fCust,d_Pay,fPay,d_Date,">="&$C43,d_Date,"<="&$D43) -> 17542.9 | I43: =SUMIFS(d_NP,d_Category,fCat,d_City,fCity,d_Cust,fCust,d_Pay,fPay,d_Date,">="&$C43,d_Date,"<="&$D43) -> 11793.7 | J43: =SUMIFS(d_Qty,d_Category,fCat,d_City,fCity,d_Cust,fCust,d_Pay,fPay,d_Date,">="&$C43,d_Date,"<="&$D43) -> 495 | K43: =SUMIFS(d_RetQty,d_Category,fCat,d_City,fCity,d_Cust,fCust,d_Pay,fPay,d_Date,">="&$C43,d_Date,"<="&$D43) -> 9 | L43: =SUMIFS(d_NetQty,d_Category,fCat,d_City,fCity,d_Cust,fCust,d_Pay,fPay,d_Date,">="&$C43,d_Date,"<="&$D43) -> 486 | M43: =COUNTIFS(d_Category,fCat,d_City,fCity,d_Cust,fCust,d_Pay,fPay,d_Date,">="&$C43,d_Date,"<="&$D43) -> 161 | N43: =IF(G43=0,0,H43/G43) -> 0.27098316 | O43: =IF(G43=0,0,I43/G43) -> 0.18217593 | P43: =IF(J43=0,0,K43/J43) -> 0.018181818 | Q43: =IF(M43=0,0,G43/M43) -> 402.09919 | R43: =IF(G43>0,G43,1E+99) -> 64737.97
A44: 8 | B44: Aug | C44: =DATE($C$11,A44,1) -> 45870 | D44: =EOMONTH(C44,0) -> 45900 | E44: =SUMIFS(d_Sales,d_Category,fCat,d_City,fCity,d_Cust,fCust,d_Pay,fPay,d_Date,">="&$C44,d_Date,"<="&$D44) -> 80130.46 | F44: =SUMIFS(d_SalesRet,d_Category,fCat,d_City,fCity,d_Cust,fCust,d_Pay,fPay,d_Date,">="&$C44,d_Date,"<="&$D44) -> 1029 | G44: =SUMIFS(d_NetSales,d_Category,fCat,d_City,fCity,d_Cust,fCust,d_Pay,fPay,d_Date,">="&$C44,d_Date,"<="&$D44) -> 79101.46 | H44: =SUMIFS(d_GP,d_Category,fCat,d_City,fCity,d_Cust,fCust,d_Pay,fPay,d_Date,">="&$C44,d_Date,"<="&$D44) -> 19450.45 | I44: =SUMIFS(d_NP,d_Category,fCat,d_City,fCity,d_Cust,fCust,d_Pay,fPay,d_Date,">="&$C44,d_Date,"<="&$D44) -> 12142.13 | J44: =SUMIFS(d_Qty,d_Category,fCat,d_City,fCity,d_Cust,fCust,d_Pay,fPay,d_Date,">="&$C44,d_Date,"<="&$D44) -> 622 | K44: =SUMIFS(d_RetQty,d_Category,fCat,d_City,fCity,d_Cust,fCust,d_Pay,fPay,d_Date,">="&$C44,d_Date,"<="&$D44) -> 15 | L44: =SUMIFS(d_NetQty,d_Category,fCat,d_City,fCity,d_Cust,fCust,d_Pay,fPay,d_Date,">="&$C44,d_Date,"<="&$D44) -> 607 | M44: =COUNTIFS(d_Category,fCat,d_City,fCity,d_Cust,fCust,d_Pay,fPay,d_Date,">="&$C44,d_Date,"<="&$D44) -> 185 | N44: =IF(G44=0,0,H44/G44) -> 0.24589243 | O44: =IF(G44=0,0,I44/G44) -> 0.15350071 | P44: =IF(J44=0,0,K44/J44) -> 0.024115756 | Q44: =IF(M44=0,0,G44/M44) -> 427.57546 | R44: =IF(G44>0,G44,1E+99) -> 79101.46
...
